Workbook

Sheet À lire
A1: Routing mensuel Atom — validation des lieux et des points GPS (17/10/2026)
A3: Pourquoi ce fichier
A4: Le 17/10, deux merchandisers (Zogbolou Kevin, Abbé Frédéric) ont reçu dans l'application des PDV d'une autre zone que celle prévue.
A5: Cause : dans le fichier de routing du 10/10, certains points GPS ne tombent pas sur le lieu de visite. L'application prend les PDV à moins de 500 m de ce point.
A6: Nous avons comparé chaque point avec OpenStreetMap et avec le quartier des PDV. 24 points ont été corrigés ; d'autres restent à confirmer par Atom.
A8: Ce que nous vous demandons
A9: 1. Onglet « Routing » : remplir les cellules jaunes. « Validation Atom » : Oui (ligne juste) ou Non (à corriger). Si Non, écrire le bon lieu ou le bon point GPS (copié de Google Maps) dans « Correction Atom ».
A10: Les lignes « À confirmer (douteux) » sont prioritaires ; les lignes « Corrigé le 17/10 » sont à vérifier.
A11: 2. Onglet « Semaines octobre » : indiquer, dans la colonne jaune, le numéro de semaine (Occurrence 1 à 4) que vous utilisez pour chaque date.
A12: Exemple : le samedi 17/10, l'application compte la semaine 3 (Attécoubé 2 pour Abbé). Abbé attendait la semaine 2 (Dallas 1). Lequel est juste ?
A13: 3. Abbé Frédéric : son planning a-t-il changé après la réaffectation du 16/10 ? Si oui, merci d'envoyer le nouveau fichier.
A15: Exemple de ligne remplie (onglet « Routing ») :
... A26: Sources : base de l'application (17/10/2026, 12 h), OpenStreetMap / Nominatim (© contributeurs OpenStreetMap, licence ODbL).

Sheet Synthèse
A1: Merchandiser | B1: Cases | C1: OK | D1: Corrigé le 17/10 | E1: À confirmer (douteux) | F1: À confirmer (non vérifiable) | G1: Validées par Atom
A2: ABBE FREDERIC | B2: =COUNTIFS(Routing!$A$2:$A$216,$A2) -> 24 | C2: =COUNTIFS(Routing!$A$2:$A$216,$A2,Routing!$I$2:$I$216,"OK") -> 12 | D2: =COUNTIFS(Routing!$A$2:$A$216,$A2,Routing!$I$2:$I$216,"Corrigé le 17/10") -> 8 | E2: =COUNTIFS(Routing!$A$2:$A$216,$A2,Routing!$I$2:$I$216,"À confirmer (douteux)") -> 3 | F2: =COUNTIFS(Routing!$A$2:$A$216,$A2,Routing!$I$2:$I$216,"À confirmer (non vérifiable)") -> 1 | G2: =COUNTIFS(Routing!$A$2:$A$216,$A2,Routing!$P$2:$P$216,"Oui") -> 0
A3: DEHEO WILFRIED | B3: =COUNTIFS(Routing!$A$2:$A$216,$A3) -> 23 | C3: =COUNTIFS(Routing!$A$2:$A$216,$A3,Routing!$I$2:$I$216,"OK") -> 19 | D3: =COUNTIFS(Routing!$A$2:$A$216,$A3,Routing!$I$2:$I$216,"Corrigé le 17/10") -> 2 | E3: =COUNTIFS(Routing!$A$2:$A$216,$A3,Routing!$I$2:$I$216,"À confirmer (douteux)") -> 2 | F3: =COUNTIFS(Routing!$A$2:$A$216,$A3,Routing!$I$2:$I$216,"À confirmer (non vérifiable)") -> 0 | G3: =COUNTIFS(Routing!$A$2:$A$216,$A3,Routing!$P$2:$P$216,"Oui") -> 0
A4: GUI STEPHANE | B4: =COUNTIFS(Routing!$A$2:$A$216,$A4) -> 24 | C4: =COUNTIFS(Routing!$A$2:$A$216,$A4,Routing!$I$2:$I$216,"OK") -> 16 | D4: =COUNTIFS(Routing!$A$2:$A$216,$A4,Routing!$I$2:$I$216,"Corrigé le 17/10") -> 1 | E4: =COUNTIFS(Routing!$A$2:$A$216,$A4,Routing!$I$2:$I$216,"À confirmer (douteux)") -> 2 | F4: =COUNTIFS(Routing!$A$2:$A$216,$A4,Routing!$I$2:$I$216,"À confirmer (non vérifiable)") -> 5 | G4: =COUNTIFS(Routing!$A$2:$A$216,$A4,Routing!$P$2:$P$216,"Oui") -> 0
A5: GUIHI BERNADIN | B5: =COUNTIFS(Routing!$A$2:$A$216,$A5) -> 24 | C5: =COUNTIFS(Routing!$A$2:$A$216,$A5,Routing!$I$2:$I$216,"OK") -> 18 | D5: =COUNTIFS(Routing!$A$2:$A$216,$A5,Routing!$I$2:$I$216,"Corrigé le 17/10") -> 1 | E5: =COUNTIFS(Routing!$A$2:$A$216,$A5,Routing!$I$2:$I$216,"À confirmer (douteux)") -> 3 | F5: =COUNTIFS(Routing!$A$2:$A$216,$A5,Routing!$I$2:$I$216,"À confirmer (non vérifiable)") -> 2 | G5: =COUNTIFS(Routing!$A$2:$A$216,$A5,Routing!$P$2:$P$216,"Oui") -> 0
A6: KOUADIO ATOFFE GUY ANICET | B6: =COUNTIFS(Routing!$A$2:$A$216,$A6) -> 24 | C6: =COUNTIFS(Routing!$A$2:$A$216,$A6,Routing!$I$2:$I$216,"OK") -> 18 | D6: =COUNTIFS(Routing!$A$2:$A$216,$A6,Routing!$I$2:$I$216,"Corrigé le 17/10") -> 1 | E6: =COUNTIFS(Routing!$A$2:$A$216,$A6,Routing!$I$2:$I$216,"À confirmer (douteux)") -> 3 | F6: =COUNTIFS(Routing!$A$2:$A$216,$A6,Routing!$I$2:$I$216,"À confirmer (non vérifiable)") -> 2 | G6: =COUNTIFS(Routing!$A$2:$A$216,$A6,Routing!$P$2:$P$216,"Oui") -> 0
A7: KOUAME HELLARION | B7: =COUNTIFS(Routing!$A$2:$A$216,$A7) -> 24 | C7: =COUNTIFS(Routing!$A$2:$A$216,$A7,Routing!$I$2:$I$216,"OK") -> 16 | D7: =COUNTIFS(Routing!$A$2:$A$216,$A7,Routing!$I$2:$I$216,"Corrigé le 17/10") -> 0 | E7: =COUNTIFS(Routing!$A$2:$A$216,$A7,Routing!$I$2:$I$216,"À confirmer (douteux)") -> 8 | F7: =COUNTIFS(Routing!$A$2:$A$216,$A7,Routing!$I$2:$I$216,"À confirmer (non vérifiable)") -> 0 | G7: =COUNTIFS(Routing!$A$2:$A$216,$A7,Routing!$P$2:$P$216,"Oui") -> 0
A8: SEREGONE SCHADRACK | B8: =COUNTIFS(Routing!$A$2:$A$216,$A8) -> 24 | C8: =COUNTIFS(Routing!$A$2:$A$216,$A8,Routing!$I$2:$I$216,"OK") -> 13 | D8: =COUNTIFS(Routing!$A$2:$A$216,$A8,Routing!$I$2:$I$216,"Corrigé le 17/10") -> 0 | E8: =COUNTIFS(Routing!$A$2:$A$216,$A8,Routing!$I$2:$I$216,"À confirmer (douteux)") -> 4 | F8: =COUNTIFS(Routing!$A$2:$A$216,$A8,Routing!$I$2:$I$216,"À confirmer (non vérifiable)") -> 7 | G8: =COUNTIFS(Routing!$A$2:$A$216,$A8,Routing!$P$2:$P$216,"Oui") -> 0
A9: YAO VENANCE | B9: =COUNTIFS(Routing!$A$2:$A$216,$A9) -> 24 | C9: =COUNTIFS(Routing!$A$2:$A$216,$A9,Routing!$I$2:$I$216,"OK") -> 14 | D9: =COUNTIFS(Routing!$A$2:$A$216,$A9,Routing!$I$2:$I$216,"Corrigé le 17/10") -> 2 | E9: =COUNTIFS(Routing!$A$2:$A$216,$A9,Routing!$I$2:$I$216,"À confirmer (douteux)") -> 4 | F9: =COUNTIFS(Routing!$A$2:$A$216,$A9,Routing!$I$2:$I$216,"À confirmer (non vérifiable)") -> 4 | G9: =COUNTIFS(Routing!$A$2:$A$216,$A9,Routing!$P$2:$P$216,"Oui") -> 0
A10: ZOGBOLOU KEVIN | B10: =COUNTIFS(Routing!$A$2:$A$216,$A10) -> 24 | C10: =COUNTIFS(Routing!$A$2:$A$216,$A10,Routing!$I$2:$I$216,"OK") -> 15 | D10: =COUNTIFS(Routing!$A$2:$A$216,$A10,Routing!$I$2:$I$216,"Corrigé le 17/10") -> 9 | E10: =COUNTIFS(Routing!$A$2:$A$216,$A10,Routing!$I$2:$I$216,"À confirmer (douteux)") -> 0 | F10: =COUNTIFS(Routing!$A$2:$A$216,$A10,Routing!$I$2:$I$216,"À confirmer (non vérifiable)") -> 0 | G10: =COUNTIFS(Routing!$A$2:$A$216,$A10,Routing!$P$2:$P$216,"Oui") -> 0
A11: Total | B11: =SUM(B2:B10) -> 215 | C11: =SUM(C2:C10) -> 141 | D11: =SUM(D2:D10) -> 24 | E11: =SUM(E2:E10) -> 29 | F11: =SUM(F2:F10) -> 21 | G11: =SUM(G2:G10) -> 0

Sheet Routing
A1: Merchandiser | B1: Jour | C1: Semaine | D1: Point de visite | E1: Commune | F1: Distributeur | G1: SSF | H1: Engin | I1: Statut | J1: Point GPS utilisé | K1: Carte | L1: Ancien point (agence) | M1: Écart (m) | N1: Explication | O1: Suggestion OpenStreetMap | P1: Validation Atom | Q1: Correction Atom
A2: ABBE FREDERIC | B2: Lundi | C2: S1 | D2: 220 Logements 1 | E2: Adjamé | F2: BOUSSOURA SARL | G2: Tra Bi Ta Arsène | H2: Mini van | I2: OK | J2: 5.35800, -4.02100 | K2: Carte | N2: Point à 795 m du lieu trouvé sur OpenStreetMap
A3: ABBE FREDERIC | B3: Mardi | C3: S1 | D3: Agban village | E3: Attécoubé | F3: BOUSSOURA SARL | G3: Kouadio Kouadio Morel Arsène | H3: Mini van | I3: OK | J3: 5.36023, -4.03334 | K3: Carte | N3: Point à 1 m du lieu trouvé sur OpenStreetMap
A4: ABBE FREDERIC | B4: Mercredi | C4: S1 | D4: Quartier Ébrié | E4: Adjamé | F4: BOUSSOURA SARL | G4: Yapi Wilfried Landry Élisé | H4: Mini van | I4: OK | J4: 5.35529, -4.02076 | K4: Carte | N4: Point à 0 m du lieu trouvé sur OpenStreetMap
A5: ABBE FREDERIC | B5: Jeudi | C5: S1 | D5: Paillet | E5: Adjamé (Williamsville) | F5: BOUSSOURA SARL | G5: Edgar Koissi Attowla Yao | H5: Mini van | I5: À confirmer (douteux) | J5: 5.37671, -4.01332 | K5: Carte | N5: Lieu introuvable sur OpenStreetMap ; PDV du quartier reconnu à 1016 m du point
A6: ABBE FREDERIC | B6: Vendredi | C6: S1 | D6: Cité Rane | E6: Adjamé | F6: BOUSSOURA SARL | G6: Diallo Souleymane | H6: Mini van | I6: À confirmer (non vérifiable) | J6: 5.36400, -4.02400 | K6: Carte | N6: Lieu introuvable sur OpenStreetMap et aucun quartier de PDV reconnu : point non vérifiable
A7: ABBE FREDERIC | B7: Samedi | C7: S1 | D7: Bracodi | E7: Adjamé | F7: BOUSSOURA SARL | G7: Tamdia Aliou | H7: Grossiste | I7: OK | J7: 5.36160, -4.02523 | K7: Carte | N7: Point à 0 m du lieu trouvé sur OpenStreetMap
A8: ABBE FREDERIC | B8: Lundi | C8: S2 | D8: 220 Logements 2 | E8: Adjamé | F8: BOUSSOURA SARL | G8: Tra Bi Ta Arsène | H8: Mini van | I8: OK | J8: 5.35950, -4.02250 | K8: Carte | N8: PDV du quartier reconnu à 100 m du point
A9: ABBE FREDERIC | B9: Mardi | C9: S2 | D9: Attécoubé 1 | E9: Attécoubé | F9: BOUSSOURA SARL | G9: Kouadio Kouadio Morel Arsène | H9: Mini van | I9: À confirmer (douteux) | J9: 5.33700, -4.03200 | K9: Carte | N9: Point à 511 m des PDV notés ATTECOUBE (limite) ; le centre de ces PDV tombe côté Adjamé. | O9: 5.35151, -4.05196 (« Attécoubé 3 »)
A10: ABBE FREDERIC | B10: Mercredi | C10: S2 | D10: Dallas 1 | E10: Adjamé | F10: BOUSSOURA SARL | G10: Yapi Wilfried Landry Élisé | H10: Mini van | I10: Corrigé le 17/10 | J10: 5.34191, -4.02370 | K10: Carte | L10: 5.33200, -4.03900 | M10: 2021 | N10: OpenStreetMap « Carrefour Dallas »
A11: ABBE FREDERIC | B11: Jeudi | C11: S2 | D11: Williamsville 1 | E11: Adjamé (Williamsville) | F11: BOUSSOURA SARL | G11: Edgar Koissi Attowla Yao | H11: Mini van | I11: Corrigé le 17/10 | J11: 5.37375, -4.02510 | K11: Carte | L11: 5.37200, -4.01800 | M11: 810 | N11: Centre des PDV du quartier (lieu introuvable sur OpenStreetMap)
A12: ABBE FREDERIC | B12: Vendredi | C12: S2 | D12: Bramakoté 1 | E12: Adjamé | F12: BOUSSOURA SARL | G12: Diallo Souleymane | H12: Mini van | I12: Corrigé le 17/10 | J12: 5.34927, -4.03242 | K12: Carte | L12: 5.36100, -4.02900 | M12: 1358 | N12: Centre des PDV du quartier (lieu introuvable sur OpenStreetMap)
A13: ABBE FREDERIC | B13: Samedi | C13: S2 | D13: Dallas 1 | E13: Adjamé | F13: BOUSSOURA SARL | G13: Kouadio Kouassi Pacôme | H13: Moto | I13: Corrigé le 17/10 | J13: 5.34191, -4.02370 | K13: Carte | L13: 5.33200, -4.03900 | M13: 2021 | N13: OpenStreetMap « Carrefour Dallas »
A14: ABBE FREDERIC | B14: Lundi | C14: S3 | D14: Bracodi 1 | E14: Adjamé | F14: BOUSSOURA SARL | G14: Tra Bi Ta Arsène | H14: Mini van | I14: Corrigé le 17/10 | J14: 5.36160, -4.02523 | K14: Carte | L14: 5.35200, -4.02500 | M14: 1068 | N14: OpenStreetMap « Bracodi »
A15: ABBE FREDERIC | B15: Mardi | C15: S3 | D15: Attécoubé 2 | E15: Attécoubé | F15: BOUSSOURA SARL | G15: Kouadio Kouadio Morel Arsène | H15: Mini van | I15: OK | J15: 5.33850, -4.03350 | K15: Carte | N15: PDV du quartier reconnu à 409 m du point
A16: ABBE FREDERIC | B16: Mercredi | C16: S3 | D16: Saint Michel 1 | E16: Adjamé | F16: BOUSSOURA SARL | G16: Yapi Wilfried Landry Élisé | H16: Mini van | I16: Corrigé le 17/10 | J16: 5.34548, -4.02202 | K16: Carte | L16: 5.35500, -4.02300 | M16: 1064 | N16: OpenStreetMap « Saint-Michel »
A17: ABBE FREDERIC | B17: Jeudi | C17: S3 | D17: Vidange | E17: Adjamé (Williamsville) | F17: BOUSSOURA SARL | G17: Edgar Koissi Attowla Yao | H17: Mini van | I17: À confirmer (douteux) | J17: 5.38519, -4.00601 | K17: Carte | N17: Lieu introuvable sur OpenStreetMap ; PDV du quartier reconnu à 2059 m du point
A18: ABBE FREDERIC | B18: Vendredi | C18: S3 | D18: Bramakoté 2 | E18: Adjamé | F18: BOUSSOURA SARL | G18: Diallo Souleymane | H18: Mini van | I18: Corrigé le 17/10 | J18: 5.34927, -4.03242 | K18: Carte | L18: 5.36250, -4.03050 | M18: 1486 | N18: Centre des PDV du quartier (lieu introuvable sur OpenStreetMap)
A19: ABBE FREDERIC | B19: Samedi | C19: S3 | D19: Attécoubé 2 | E19: Attécoubé | F19: BOUSSOURA SARL | G19: Tamdia Aliou | H19: Grossiste | I19: OK | J19: 5.33850, -4.03350 | K19: Carte | N19: PDV du quartier reconnu à 409 m du point
A20: ABBE FREDERIC | B20: Lundi | C20: S4 | D20: Bracodi 2 | E20: Adjamé | F20: BOUSSOURA SARL | G20: Tra Bi Ta Arsène | H20: Mini van | I20: OK | J20: 5.35350, -4.02650 | K20: Carte | N20: Point à 911 m du lieu trouvé sur OpenStreetMap
A21: ABBE FREDERIC | B21: Mardi | C21: S4 | D21: Cité Fairmont et Attécoubé 2 | E21: Attécoubé | F21: BOUSSOURA SARL | G21: Kouadio Kouadio Morel Arsène | H21: Mini van | I21: OK | J21: 5.34000, -4.03100 | K21: Carte | N21: PDV du quartier reconnu à 182 m du point
A22: ABBE FREDERIC | B22: Mercredi | C22: S4 | D22: Dallas 2 | E22: Adjamé | F22: BOUSSOURA SARL | G22: Yapi Wilfried Landry Élisé | H22: Mini van | I22: Corrigé le 17/10 | J22: 5.34191, -4.02370 | K22: Carte | L22: 5.33350, -4.04050 | M22: 2082 | N22: OpenStreetMap « Carrefour Dallas »
A23: ABBE FREDERIC | B23: Jeudi | C23: S4 | D23: HMA | E23: Adjamé (Williamsville) | F23: BOUSSOURA SARL | G23: Edgar Koissi Attowla Yao | H23: Mini van | I23: OK | J23: 5.38132, -4.00742 | K23: Carte | N23: Point à 954 m du lieu trouvé sur OpenStreetMap
A24: ABBE FREDERIC | B24: Vendredi | C24: S4 | D24: Délégation | E24: Adjamé | F24: BOUSSOURA SARL | G24: Diallo Souleymane | H24: Mini van | I24: OK | J24: 5.34325, -4.02980 | K24: Carte | N24: Point à 0 m du lieu trouvé sur OpenStreetMap
A25: ABBE FREDERIC | B25: Samedi | C25: S4 | D25: Quartier rouge | E25: Adjamé | F25: BOUSSOURA SARL | G25: Tamdia Aliou | H25: Grossiste | I25: OK | J25: 5.35080, -4.02050 | K25: Carte | N25: PDV du quartier reconnu à 14 m du point
A26: DEHEO WILFRIED | B26: Lundi | C26: S1 | D26: Sable et Institut des aveugles | E26: Yopougon | F26: SODICOM-CI | G26: Koné Moussa | H26: Mini van | I26: Corrigé le 17/10 | J26: 5.35705, -4.06819 | K26: Carte | L26: 5.33800, -4.07800 | M26: 2380 | N26: OpenStreetMap « Sable »
A27: DEHEO WILFRIED | B27: Mardi | C27: S1 | D27: Niangon | E27: Yopougon | F27: SODICOM-CI | G27: Yapi Amandine | H27: Mini van | I27: OK | J27: 5.32358, -4.09822 | K27: Carte | N27: Point à 1 m du lieu trouvé sur OpenStreetMap
A28: DEHEO WILFRIED | B28: Mercredi | C28: S1 | D28: Selmer | E28: Yopougon | F28: SODICOM-CI | G28: Kouamé Guillaume | H28: Mini van | I28: OK | J28: 5.34037, -4.07002 | K28: Carte | N28: Point à 0 m du lieu trouvé sur OpenStreetMap
A29: DEHEO WILFRIED | B29: Jeudi | C29: S1 | D29: Koweït | E29: Yopougon | F29: SODICOM-CI | G29: Konan Kan Franck | H29: Mini van | I29: OK | J29: 5.32218, -4.05427 | K29: Carte | N29: Point à 109 m du lieu trouvé sur OpenStreetMap
A30: DEHEO WILFRIED | B30: Vendredi | C30: S1 | D30: Petit Toit rouge | E30: Yopougon | F30: SODICOM-CI | G30: Zoro Bi Arthur | H30: Mini van | I30: OK | J30: 5.32412, -4.06695 | K30: Carte | N30: Point à 172 m du lieu trouvé sur OpenStreetMap
A31: DEHEO WILFRIED | B31: Samedi | C31: S1 | D31: Base CIE | E31: Yopougon | F31: SODICOM-CI | G31: Bakayoko Alassane | H31: Moto | I31: OK | J31: 5.33219, -4.08947 | K31: Carte | N31: Point à 13 m du lieu trouvé sur OpenStreetMap
A32: DEHEO WILFRIED | B32: Lundi | C32: S2 | D32: Millionnaire | E32: Yopougon | F32: SODICOM-CI | G32: Koné Moussa | H32: Mini van | I32: OK | J32: 5.35429, -4.06024 | K32: Carte | N32: Point à 0 m du lieu trouvé sur OpenStreetMap
A33: DEHEO WILFRIED | B33: Mardi | C33: S2 | D33: Camp militaire | E33: Yopougon | F33: SODICOM-CI | G33: Yapi Amandine | H33: Mini van | I33: OK | J33: 5.32157, -4.06465 | K33: Carte | N33: Point à 1 m du lieu trouvé sur OpenStreetMap
A34: DEHEO WILFRIED | B34: Mercredi | C34: S2 | D34: Sicogi | E34: Yopougon | F34: SODICOM-CI | G34: Kouamé Guillaume | H34: Mini van | I34: OK | J34: 5.34409, -4.07743 | K34: Carte | N34: Point à 0 m du lieu trouvé sur OpenStreetMap
A35: DEHEO WILFRIED | B35: Jeudi | C35: S2 | D35: Koweït 2 et Agbayaté 1 | E35: Yopougon | F35: SODICOM-CI | G35: Konan Kan Franck | H35: Mini van | I35: Corrigé le 17/10 | J35: 5.32122, -4.05446 | K35: Carte | L35: 5.32100, -4.09200 | M35: 4156 | N35: OpenStreetMap « Koweit »
A36: DEHEO WILFRIED | B36: Vendredi | C36: S2 | D36: Kouté | E36: Yopougon | F36: SODICOM-CI | G36: Zoro Bi Arthur | H36: Mini van | I36: OK | J36: 5.32514, -4.07331 | K36: Carte | N36: Point à 0 m du lieu trouvé sur OpenStreetMap
A37: DEHEO WILFRIED | B37: Samedi | C37: S2 | D37: Locodjro | E37: Yopougon | F37: SODICOM-CI | G37: Yao Jaurès | H37: Moto | I37: OK | J37: 5.32641, -4.04112 | K37: Carte | N37: PDV du quartier reconnu à 151 m du point
A38: DEHEO WILFRIED | B38: Lundi | C38: S3 | D38: Nouveau quartier | E38: Yopougon | F38: SODICOM-CI | G38: Koné Moussa | H38: Mini van | I38: OK | J38: 5.33959, -4.05924 | K38: Carte | N38: Point à 0 m du lieu trouvé sur OpenStreetMap
A39: DEHEO WILFRIED | B39: Mardi | C39: S3 | D39: Sideci LEM | E39: Yopougon | F39: SODICOM-CI | G39: Yapi Amandine | H39: Mini van | I39: OK | J39: 5.33100, -4.08400 | K39: Carte | N39: Point à 766 m du lieu trouvé sur OpenStreetMap
A40: DEHEO WILFRIED | B40: Mercredi | C40: S3 | D40: Complexe | E40: Yopougon | F40: SODICOM-CI | G40: Kouamé Guillaume | H40: Mini van | I40: OK | J40: 5.34141, -4.06502 | K40: Carte | N40: Point à 1 m du lieu trouvé sur OpenStreetMap
...

Sheet Semaines octobre
A1: Date | B1: Jour | C1: Semaine selon l'application (jours 1-7 = S1) | D1: Semaine si on compte à partir du 1er lundi | E1: Semaine selon Atom
A2: 46296 | B2: =CHOOSE(WEEKDAY(A2,2),"Lundi","Mardi","Mercredi","Jeudi","Vendredi","Samedi","Dimanche") -> Jeudi | C2: =INT((DAY(A2)-1)/7)+1 -> 1 | D2: =INT((DAY(A2-WEEKDAY(A2,3))-1)/7)+1 -> 4
A3: 46297 | B3: =CHOOSE(WEEKDAY(A3,2),"Lundi","Mardi","Mercredi","Jeudi","Vendredi","Samedi","Dimanche") -> Vendredi | C3: =INT((DAY(A3)-1)/7)+1 -> 1 | D3: =INT((DAY(A3-WEEKDAY(A3,3))-1)/7)+1 -> 4
A4: 46298 | B4: =CHOOSE(WEEKDAY(A4,2),"Lundi","Mardi","Mercredi","Jeudi","Vendredi","Samedi","Dimanche") -> Samedi | C4: =INT((DAY(A4)-1)/7)+1 -> 1 | D4: =INT((DAY(A4-WEEKDAY(A4,3))-1)/7)+1 -> 4
A5: 46300 | B5: =CHOOSE(WEEKDAY(A5,2),"Lundi","Mardi","Mercredi","Jeudi","Vendredi","Samedi","Dimanche") -> Lundi | C5: =INT((DAY(A5)-1)/7)+1 -> 1 | D5: =INT((DAY(A5-WEEKDAY(A5,3))-1)/7)+1 -> 1
A6: 46301 | B6: =CHOOSE(WEEKDAY(A6,2),"Lundi","Mardi","Mercredi","Jeudi","Vendredi","Samedi","Dimanche") -> Mardi | C6: =INT((DAY(A6)-1)/7)+1 -> 1 | D6: =INT((DAY(A6-WEEKDAY(A6,3))-1)/7)+1 -> 1
A7: 46302 | B7: =CHOOSE(WEEKDAY(A7,2),"Lundi","Mardi","Mercredi","Jeudi","Vendredi","Samedi","Dimanche") -> Mercredi | C7: =INT((DAY(A7)-1)/7)+1 -> 1 | D7: =INT((DAY(A7-WEEKDAY(A7,3))-1)/7)+1 -> 1
A8: 46303 | B8: =CHOOSE(WEEKDAY(A8,2),"Lundi","Mardi","Mercredi","Jeudi","Vendredi","Samedi","Dimanche") -> Jeudi | C8: =INT((DAY(A8)-1)/7)+1 -> 2 | D8: =INT((DAY(A8-WEEKDAY(A8,3))-1)/7)+1 -> 1
A9: 46304 | B9: =CHOOSE(WEEKDAY(A9,2),"Lundi","Mardi","Mercredi","Jeudi","Vendredi","Samedi","Dimanche") -> Vendredi | C9: =INT((DAY(A9)-1)/7)+1 -> 2 | D9: =INT((DAY(A9-WEEKDAY(A9,3))-1)/7)+1 -> 1
A10: 46305 | B10: =CHOOSE(WEEKDAY(A10,2),"Lundi","Mardi","Mercredi","Jeudi","Vendredi","Samedi","Dimanche") -> Samedi | C10: =INT((DAY(A10)-1)/7)+1 -> 2 | D10: =INT((DAY(A10-WEEKDAY(A10,3))-1)/7)+1 -> 1
A11: 46307 | B11: =CHOOSE(WEEKDAY(A11,2),"Lundi","Mardi","Mercredi","Jeudi","Vendredi","Samedi","Dimanche") -> Lundi | C11: =INT((DAY(A11)-1)/7)+1 -> 2 | D11: =INT((DAY(A11-WEEKDAY(A11,3))-1)/7)+1 -> 2
A12: 46308 | B12: =CHOOSE(WEEKDAY(A12,2),"Lundi","Mardi","Mercredi","Jeudi","Vendredi","Samedi","Dimanche") -> Mardi | C12: =INT((DAY(A12)-1)/7)+1 -> 2 | D12: =INT((DAY(A12-WEEKDAY(A12,3))-1)/7)+1 -> 2
A13: 46309 | B13: =CHOOSE(WEEKDAY(A13,2),"Lundi","Mardi","Mercredi","Jeudi","Vendredi","Samedi","Dimanche") -> Mercredi | C13: =INT((DAY(A13)-1)/7)+1 -> 2 | D13: =INT((DAY(A13-WEEKDAY(A13,3))-1)/7)+1 -> 2
... A28: 46326 | B28: =CHOOSE(WEEKDAY(A28,2),"Lundi","Mardi","Mercredi","Jeudi","Vendredi","Samedi","Dimanche") -> Samedi | C28: =INT((DAY(A28)-1)/7)+1 -> 5 | D28: =INT((DAY(A28-WEEKDAY(A28,3))-1)/7)+1 -> 4
A30: Ligne en gras : samedi 17/10. Colonne D = semaine du lundi de la date (du 1er au 4/10, ce lundi est le 28/09, donc semaine 4 de septembre).
